Workbook

Sheet Lineas de Credito
A2: LINEAS DE CREDITOS VIGENTES
A4: N° | B4: Linea | C4: Descripción Producto | D4: Tasa | E4: Tipo_Cartera | F4: Desprotegido Max | H4: Credito Afianzado
A5: 1 | B5: 1023 | C5: Compra Cartera | D5: 0.01 | E5: Consumo | H5: SI
A6: 2 | B6: 1024 | C6: Cred. Ord. Ant. Cinco Años | H6: NO
A7: 3 | B7: 1025 | C7: Credito Empleados
A8: 4 | B8: 1026 | C8: Credito Ordinario
A9: 5 | B9: 1028 | C9: Cred. Ord. Ant. Quince Años
A10: 6 | B10: 1031 | C10: Ptmo.Ord.No24
A11: 7 | B11: 1032 | C11: Credito De Vehiculo
A12: 8 | B12: 1034 | C12: Ptmo.Ant.Prim
A13: 9 | B13: 1035 | C13: Educativo
A14: 10 | B14: 1037 | C14: Orden Comercio
A15: 11 | B15: 1042 | C15: Eventos
A16: 12 | B16: 1043 | C16: Cred. Ord. Ant. Diez Años
A17: 13 | B17: 1050 | C17: Polizas Soat
A18: 14 | B18: 1053 | C18: Turismo Orden
... A29: 25 | B29: 1067 | C29: Cupo Rotativo Avance
A30: 26
A31: 27
A32: 28
A33: 29
A34: 30
A35: 31
A36: 32
A37: 33
A38: 34
A39: 35
A40: 36
A41: 37
... A203: 199

Sheet Ponderación
A1: NUEVA PONDERACION
A2: 1. EDAD
A3: AÑOS | C3: PONDERACION
A4: 18-25 | C4: 2
A5: 26-45 | C5: 4
A6: 46-60 | C6: 3
A7: MAYOR DE 60 | C7: 1
C8: =SUM(C4:C7) -> 10
A9: 0. AHORROS EN EL FONDO | H9: PONDERACION GENERAL | I9: PROP
A10: 0 | B10: 0 | C10: 0 | H10: 1. NIVEL DE RIESGO | I10: 0.3
A11: 0 | B11: 0 | C11: 0 | H11: 0. AHORROS EN EL FONDO | I11: 0
A12: 0 | B12: 0 | C12: 0 | H12: 2. USUARIO DE CREDITO EN LA COOP | I12: 0.2
A13: 0 | B13: 0 | C13: 0 | H13: 3. EDAD | I13: 0.05
C14: =SUM(C10:C13) -> 0 | H14: 4. No PERSONAS A CARGO | I14: 0.05
A15: 2. USUARIO DE CREDITO EN EL FONDO | H15: 5. TIPO DE VIVIENDA | I15: 0.1
A16: 0 | B16: 1000000 | C16: 0 | H16: 6. ANTIGÜEDAD EN LA COOPERATIVA | I16: 0.15
A17: 1000000 | B17: 5000000 | C17: 1 | H17: 7. ANTIGÜEDAD LABORAL | I17: 0.1
A18: 5000000 | B18: 10000000 | C18: 3 | H18: 8. NIVEL DE INGRESOS | I18: 0.05
A19: 10000000 | C19: 6
C20: =SUM(C16:C19) -> 10 | I20: =SUM(I10:I19) -> 1
A21: 1. NIVEL DE RIESGO
A22: 0 | B22: 200 | C22: 0
A23: 201 | B23: 500 | C23: 1
A24: 501 | B24: 795 | C24: 2 | H24: PERFIL A | I24: ENTRE 4,01 A 5.83
A25: 796 | B25: 1000 | C25: 7 | H25: PERFIL B | I25: ENTRE 2.70 A 4.00
C26: =SUM(C22:C25) -> 10 | H26: PERFIL C | I26: ENTRE 0 A 2.69
I28: A | J28: 4.01 | K28: 5.83
I29: B | J29: 2.7 | K29: 4.00
I30: C | J30: 0 | K30: 2.69
A32: 1. EDAD
A33: AÑOS | C33: PONDERACION
A34: 18 | B34: 25 | C34: 2
A35: 26 | B35: 45 | C35: 4
A36: 46 | B36: 60 | C36: 3
A37: 60 | C37: 1
C38: =SUM(C34:C37) -> 10
A39: 4. No PERSONAS A CARGO
A40: 0 | B40: 1 | C40: 5
A41: 2 | B41: 3 | C41: 3
A42: 3 | B42: 4 | C42: 2
...

Sheet Base Perfil
K1: 0 | L1: 0.2 | M1: 0.3 | N1: 0.05 | O1: 0.05 | P1: 0.1 | Q1: 0.15 | R1: 0.1 | S1: 0.05
A2: DATOS DE ENTRADA | K2: CALCULOS | U2: RESULTADOS
A3: SCORE | B3: INGRESOS | C3: AHORROS_FONDO | D3: USARIO_CREDITO | E3: EDAD | F3: PERSONAS A CARGO | G3: TIPO_VIVIENDA | H3: ANTIGÜEDAD_FONDO | I3: ANTIGÜEDAD_LABORAL | K3: AHORROS FONDO | L3: USARIO_CREDITO | M3: SCOR_NIVEL_RIESGO | N3: SCOR_EDAD | O3: SCOR_PCARGO | P3: SCOR_VIVIENDA | Q3: SCOR_ANT_COOP | R3: SCOR_ANT_LABORAL | S3: SCOR_INGRESOS | U3: TOTALES_SCOR | V3: PERFILES
A4: =+Capacidad_Endeudamiento!$C$31 -> 657 | B4: =+Capacidad_Endeudamiento!$C$25 -> 2500000 | D4: 0 | E4: 38 | F4: 1 | G4: 4 | H4: 2.8194444 | I4: 3.0694444 | K4: 0 | L4: =+IF(D4="","",IF(AND(D4>=Ponderación!$A$16,D4<=Ponderación!$B$16),Ponderación!$C$16,IF(AND(D4>Ponderación!$B$16,D4<=Ponderación!$B$17),Ponderación!$C$17,IF(AND(D4>Ponderación!$B$17,D4<=Ponderación!$B$18),Ponderación!$C$18,IF(D4>Ponderación!$A$19,Ponderación!$C$19,"Revisar"))))) -> 0 | M4: =+IF(A4="","",IF(AND(A4>Ponderación!$A$22,A4<=Ponderación!$B$22),Ponderación!$C$22,IF(AND(A4>Ponderación!$B$22,A4<=Ponderación!$B$23),Ponderación!$C$23,IF(AND(A4>Ponderación!$B$23,A4<=Ponderación!$B$24),Ponderación!$C$24,IF(AND(A4>Ponderación!$B$24,A4<=Ponderación!$B$25),Ponderación!$C$25,0))))) -> 2 | N4: =+IF(E4="","",IF(AND(E4>Ponderación!$A$34,E4<=Ponderación!$B$34),Ponderación!$C$34,IF(AND(E4>Ponderación!$B$34,E4<=Ponderación!$B$35),Ponderación!$C$35,IF(AND(E4>Ponderación!$B$35,E4<=Ponderación!$B$36),Ponderación!$C$36,IF(E4>Ponderación!$B$36,Ponderación!$C$37))))) -> 4 | O4: =+IF(F4="","",IF(AND(F4>=Ponderación!$A$40,F4<=Ponderación!$B$40),Ponderación!$C$40,IF(AND(F4>=Ponderación!$A$41,F4<=Ponderación!$B$41),Ponderación!$C$41,IF(AND(F4>=Ponderación!$A$42,F4<=Ponderación!$B$42),Ponderación!$C$42,IF(F4>Ponderación!$A$43,Ponderación!$C$43))))) -> 5 | P4: =+IF(G4="","",IF(G4=Ponderación!$B$46,Ponderación!$C$46,IF(G4=Ponderación!$B$47,Ponderación!$C$47,IF(G4=Ponderación!$B$48,Ponderación!$C$48,IF(G4=Ponderación!$B$49,Ponderación!$C$49,IF(G4=Ponderación!$B$50,0)))))) -> 0 | Q4: =+IF(H4="","",IF(AND(H4>=Ponderación!$A$53,H4<=Ponderación!$B$53),Ponderación!$C$53,IF(AND(H4>Ponderación!$B$53,H4<=Ponderación!$B$54),Ponderación!$C$54,IF(AND(H4>Ponderación!$B$54,H4<=Ponderación!$B$55),Ponderación!$C$55,IF(H4>Ponderación!$B$55,Ponderación!$C$56))))) -> 2 | R4: =+IF(I4="","",IF(AND(I4>=Ponderación!$A$59,I4<=Ponderación!$B$59),Ponderación!$C$59,IF(AND(I4>=Ponderación!$B$59,I4<=Ponderación!$B$60),Ponderación!$C$60,IF(AND(I4>Ponderación!$B$60,I4<=Ponderación!$B$61),Ponderación!$C$61,IF(I4>Ponderación!$B$61,Ponderación!$C$62))))) -> 2 | S4: =+IF(B4="","",IF(AND(B4>=Ponderación!$A$65,B4<=Ponderación!$B$65),Ponderación!$C$65,IF(AND(B4>Ponderación!$B$65,B4<=Ponderación!$B$66),Ponderación!$C$66,IF(AND(B4>Ponderación!$B$66,B4<=Ponderación!$B$67),Ponderación!$C$67,IF(B4>Ponderación!$A$68,Ponderación!$C$68))))) -> 1 | U4: =+IF(R4="","",(K4*$K$1)+(L4*$L$1)+(M4*$M$1)+(N4*$N$1)+(O4*$O$1)+(P4*$P$1)+(Q4*$Q$1)+(R4*$R$1)+(S4*$S$1)) -> 1.6 | V4: =+IF(U4="","",IFERROR(IF(AND(U4>=Ponderación!$J$28,U4<=Ponderación!$K$28),Ponderación!$I$28,IF(AND(U4>=Ponderación!$J$29,U4<=Ponderación!$K$29),Ponderación!$I$29,IF(AND(U4>=Ponderación!$J$30,U4<=Ponderación!$K$30),Ponderación!$I$30))),"Retirado")) -> C
A5: TU | B5: Base_Asociados | D5: API | E5: Base_Asociados | F5: chat input | G5: Base_Asociados | H5: Base_Asociados | I5: Base_Asociados
K6: =+IF(C4="","",IF(AND(C4>=Ponderación!$A$10,C4<=Ponderación!$B$10),Ponderación!$C$10,IF(AND(C4>Ponderación!$B$10,C4<=Ponderación!$B$11),Ponderación!$C$11,IF(AND(C4>Ponderación!$B$11,C4<=Ponderación!$B$12),Ponderación!$C$12,IF(C4>Ponderación!$A$13,Ponderación!$C$13,"Revisar")))))
U7: =+IF(S7="","",(K7*$K$1)+(L7*$L$1)+(M7*$M$1)+(N7*$N$1)+(O7*$O$1)+(P7*$P$1)+(Q7*$Q$1)+(R7*$R$1)+(S7*$S$1))
B8: Egresos Segurdad Social | C8: Minimo Vital | D8: Cuota_Sector | F8: Descuento Empresa | H8: Total Egresos
A9: Egresos Asociados | B9: =+Capacidad_Endeudamiento!$C$27 -> 200000 | C9: =+Capacidad_Endeudamiento!$C$38 -> 1250000 | D9: =+Datos_Iniciales!$C$14 -> 0 | F9: =+Datos_Iniciales!$C$13 -> 476010 | H9: =+SUM(B9:G9) -> 1926010

Sheet Evaluacion de Cartera
C1: =+IFERROR(VLOOKUP(B1,'[2]14 Análisis Limites'!$E$4:$H$613,4,FALSE()),0) -> 0 | D1: =+IFERROR(VLOOKUP(B1,'[3]14 Análisis Limites'!$E$4:$H$610,4,FALSE()),0) -> 0
B2: CC | C2: 2021 | D2: 2022 | E2: 2023
B3: 4661060 | C3: 51.605201 | D3: 43.213333 | E3: 12.521034
B4: 6135820 | C4: 10.176924 | D4: 13.3444 | E4: 8.1892857
B5: 6421806 | C5: 59.094988 | D5: 20.622667 | E5: 7.892069
B6: 8834375 | C6: 38.164896 | D6: 30.4458 | E6: 26.673966
B7: 9104444 | C7: 4.6458036 | D7: 14.067111 | E7: 16.124641
B8: 10280915 | C8: 3.5389843 | D8: 1.7104444 | E8: 0
B9: 11830463 | C9: 11.24899 | D9: 7.5826667 | E9: 8.1396552
B10: 14590506 | C10: 24.688656 | D10: 36.4296 | E10: 25.172414
B11: 14590768 | C11: 8.9166408 | D11: 5.6244 | E11: 5.2339655
B12: 14621610 | C12: 17.855295 | D12: 7.7293333 | E12: 0
B13: 14797927 | C13: 20.268728 | D13: 43.951333 | E13: 6.5644828
B14: 14837882 | C14: 3.3606083 | D14: 11.2268 | E14: 0
... B894: 1234196269 | C894: 0 | D894: 47.677 | E894: 0.078275862

Sheet BD
B1: COOPERATIVA DE TRABAJODRES DE LA FUNDACIÓN VALLE DEL LILI
B2: BASE DE DATOS CREDITOS ANALIZADOS
B4: Auxiliar | C4: =+COUNTA($B$5:$B$1048576)+5 -> 904
B5: N° CEDULA | C5: ASOCIADO | D5: EMPRESA | E5: SALARIO | F5: LÍNEA DE CRÉDITO | G5: MONTO SOLICITADO | H5: SCOR CIFIN | I5: ENDEUDAMIENTO ACTUAL | J5: ENDEUDAMIENTO PROYECTADO | K5: CME | L5: CMD | M5: PERFIL | N5: SOLVENCIA | O5: NIVEL_EDEUDAMIENTO | P5: TASA | Q5: GARANTIA | R5: DEUDA SECTOR | S5: OBSERVACIONES | T5: FECHA
B6: 5208653 | C6: Guerrero Rosero Jesus Orlando | D6: FVL | E6: 4480000 | F6: Compra Cartera | G6: 0 | H6: 0 | I6: 0 | K6: 22.35251 | M6: C | N6: 0.58 | O6: 22.35251 | P6: 0.0099 | Q6: Aportes | R6: 100000000 | S6: 0 | T6: 45264.661
B7: 1234190116 | C7: Ortega Conda Hebert Augusto | D7: FVL | E7: 2320800 | F7: Educativo | G7: 6548095 | H7: 810 | I7: 0.41 | J7: 0.47 | K7: 6.4249832 | L7: 0.47 | M7: B | N7: 1.5768675 | O7: 6.4249832 | P7: 0.0099 | Q7: Aportes | R7: 11563000 | S7: 0 | T7: 45303.588
B8: 1010091223 | C8: Gonzalez Triviño Karen Yuliana | D8: FVL | E8: 2383300 | F8: Credito Ordinario | G8: 4600000 | H8: 657 | I8: 0.35 | J8: 0.39 | K8: 3.2102232 | L8: 0.39 | M8: C | N8: 0.96911341 | O8: 3.2102232 | P8: 0.0099 | Q8: Aportes | R8: 163000 | S8: 0 | T8: 45303.614
B9: 1010091223 | C9: Gonzalez Triviño Karen Yuliana | D9: FVL | E9: 2383300 | F9: Credito Ordinario | G9: 3000000 | H9: 657 | I9: 0.35 | J9: 0.38 | K9: 3.2102232 | L9: 0.38 | M9: C | N9: 0.96911341 | O9: 3.2102232 | P9: 0.0099 | Q9: Aportes | R9: 163000 | S9: TIENE CREDITO AFIANZADORA | T9: 45303.624
B10: 30398858 | C10: Osorio Toro Carolina | D10: FUNDACION VALLE DEL LILI | E10: 5890200 | F10: Credito Ordinario | G10: 1600000 | H10: 747 | I10: 0.36 | J10: 0.37 | K10: 4.6435223 | L10: 0.37 | M10: C | N10: 1.5133787 | O10: 4.6435223 | P10: 0.0227 | Q10: Aportes | R10: 18050000 | S10: TIENE CREDITO AFIANZADORA | T10: 45306.354
B11: 30398858 | C11: Osorio Toro Carolina | D11: FUNDACION VALLE DEL LILI | E11: 5890200 | F11: Credito Ordinario | G11: 1600000 | H11: 747 | I11: 0.36 | J11: 0.37 | K11: 4.6435223 | L11: 0.37 | M11: C | N11: 1.5133787 | O11: 4.6435223 | P11: 0.0227 | Q11: Aportes | R11: 18050000 | S11: TIENE CREDITO AFIANZADORA | T11: 45306.356
B12: 1130605624 | C12: Pillimue Del Campo Yulieth Andrea | D12: FUNDACION VALLE DEL LILI | E12: 2648100 | F12: Educativo | G12: 6228000 | H12: 775 | I12: 0.41 | J12: 0.46 | K12: 70.736146 | L12: 0.46 | M12: B | N12: 1.5895249 | O12: 70.736146 | P12: 0.006 | Q12: Aportes | R12: 184653000 | S12: TIENE CREDITO AFIANZADORA | T12: 45306.404
B13: 1130609546 | C13: Soto Velez John Stiven | D13: FUNDACION VALLE DEL LILI | E13: 2648100 | F13: Credito Ordinario | G13: 15000000 | H13: 806 | I13: 0.3 | J13: 0.49 | K13: 2.9953552 | L13: 0.49 | M13: B | N13: 1.3515203 | O13: 2.9953552 | P13: 0.0227 | Q13: Aportes | R13: 7932000 | S13: 0 | T13: 45306.426
B14: 94492338 | C14: Millan Taguado Wilmer Jose | D14: FUNDACION VALLE DEL LILI | E14: 9417000 | F14: Credito Ordinario | G14: 3000000 | H14: 805 | I14: 0.21 | J14: 0.22 | K14: 1.1670933 | L14: 0.22 | M14: B | N14: 0.67878687 | O14: 1.1670933 | P14: 0.0227 | Q14: Aportes | R14: 0 | S14: tiene cesantias pignoradas | T14: 45306.491
B15: 1010081973 | C15: Arboleda Cuene Danessa Alejandra | D15: FUNDACION VALLE DEL LILI | E15: 2648100 | F15: Credito Ordinario | G15: 2000000 | H15: 665 | I15: 0.49 | J15: 0.46 | K15: 10.81308 | L15: 0.46 | M15: C | N15: 1.2535259 | O15: 10.81308 | P15: 0.0227 | Q15: Aportes | R15: 20451000 | S15: tiene cesantias pignoradas | T15: 45306.591
B16: 1144076114 | C16: Alzate Arce Juan Esteban | D16: FUNDACION VALLE DEL LILI | E16: 1856600 | F16: Credito Ordinario | G16: 2300000 | H16: 657 | I16: 0.07 | J16: 0.11 | K16: 0.48852742 | L16: 0.11 | M16: C | N16: 1.2985716 | O16: 0.48852742 | P16: 0.0227 | Q16: Aportes | R16: 907000 | S16: 0 | T16: 45307.36
B17: 38886733 | C17: Vela Zambrano Jakeline | D17: FUNDACION VALLE DEL LILI | E17: 4867100 | F17: Credito Afianzadora | G17: 10000000 | H17: 705 | I17: 0.35 | J17: 0.42 | K17: 17.894257 | L17: 0.42 | M17: B | N17: 1.4183068 | O17: 17.894257 | P17: 0.0222 | Q17: Aportes | R17: 77509000 | S17: 0 | T17: 45307.411
B18: 1085662084 | C18: Ortega Ortega Herson Orlando | D18: FUNDACION VALLE DEL LILI | E18: 2383300 | F18: Cred.Ord. Gerencia | G18: 1700000 | H18: 555 | I18: 0.17 | J18: 0.21 | K18: 28.826549 | L18: 0.21 | M18: C | N18: 1.6969395 | O18: 28.826549 | P18: 0.0227 | Q18: Aportes | R18: 67153000 | S18: 0 | T18: 45307.446
B19: 1123626223 | C19: Martinez Gomez Diego Alejandro | D19: FUNDACION VALLE DEL LILI | E19: 3266300 | F19: Cred.Ord. Gerencia | G19: 3000000 | H19: 726 | I19: 0.25 | J19: 0.34 | K19: 8.1073386 | L19: 0.34 | M19: C | N19: 1.3338854 | O19: 8.1073386 | P19: 0.0227 | Q19: Aportes | R19: 26481000 | S19: 0 | T19: 45307.452
B20: 1143931949 | C20: Parra Hurtado Juan Carlos | D20: FUNDACION VALLE DEL LILI | E20: 1821900 | F20: Cred.Ord. Gerencia | G20: 3480000 | H20: 578 | I20: 0.3 | J20: 0.4 | K20: 1.083638 | L20: 0.4 | M20: C | N20: 1.2293825 | O20: 1.083638 | P20: 0.0227 | Q20: Aportes | R20: 820000 | S20: recoge creditos | T20: 45307.465
B21: 1116267848 | C21: Salazar Idrobo Laura Daniela | D21: FUNDACION VALLE DEL LILI | E21: 2383300 | F21: Compra Cartera | G21: 5105000 | H21: 871 | I21: 0.06 | J21: 0.18 | K21: 0.48432006 | L21: 0.18 | M21: B | N21: 0.89696933 | O21: 0.48432006 | P21: 0.018 | Q21: Aportes | R21: 0 | S21: recoge creditos | T21: 45307.578
B22: 1113673170 | C22: Orejuela Zuñiga Yessica Lorena | D22: FUNDACION VALLE DEL LILI | E22: 2320800 | F22: Compra Cartera | G22: 2000000 | H22: 744 | I22: 0.23 | J22: 0.28 | K22: 8.3567511 | L22: 0.28 | M22: C | N22: 1.06414 | O22: 8.3567511 | P22: 0.018 | Q22: Aportes | R22: 18142000 | S22: recoge creditos | T22: 45310.712
B23: 66717390 | C23: Cruz Galvez Sandra Milena | D23: FUNDACION VALLE DEL LILI | E23: 2320800 | F23: Cred.Ord. Gerencia | G23: 1500000 | H23: 747 | I23: 0.33 | J23: 0.34 | K23: 10.951312 | L23: 0.34 | M23: C | N23: 1.0082721 | O23: 10.951312 | P23: 0.0227 | Q23: Aportes | R23: 21858000 | S23: recoge creditos | T23: 45313.556
B24: 1061543239 | C24: Zuñiga Capote Karem Julieth | D24: FUNDACION VALLE DEL LILI | E24: 2320800 | F24: Cred.Ord. Gerencia | G24: 3000000 | H24: 739 | I24: 0.13 | J24: 0.18 | K24: 3.0317132 | L24: 0.18 | M24: C | N24: 0.83609833 | O24: 3.0317132 | P24: 0.0227 | Q24: Aportes | R24: 7036000 | S24: recoge creditos | T24: 45313.699
B25: 1085661067 | C25: Solarte Martinez Yohana Estefany | D25: FUNDACION VALLE DEL LILI | E25: 2648100 | F25: Credito Ordinario | G25: 4200000 | H25: 619 | I25: 0.23 | J25: 0.4 | K25: 6.8777614 | L25: 0.4 | M25: C | N25: 4.6720384 | O25: 6.8777614 | P25: 0.0227 | Q25: Aportes | R25: 18213000 | S25: 0 | T25: 45314.318
B26: 1144175903 | C26: Agudelo Ospina Marilyn Gisela | D26: COOPVALILI | E26: 1874704 | F26: Credito Ordinario | G26: 5000000 | H26: 692 | I26: 0.25 | J26: 0.34 | K26: 17.310666 | L26: 0.34 | M26: B | N26: 1.7087025 | O26: 17.310666 | P26: 0.0227 | Q26: Aportes | R26: 18780000 | S26: 0 | T26: 45314.708
B27: 1144175903 | C27: Agudelo Ospina Marilyn Gisela | D27: COOPVALILI | E27: 1874704 | F27: Credito Afianzadora | G27: 5000000 | H27: 692 | I27: 0.25 | J27: 0.34 | K27: 17.310666 | L27: 0.34 | M27: B | N27: 1.7087025 | O27: 17.310666 | P27: 0.0227 | Q27: Aportes | R27: 18780000 | S27: 0 | T27: 45314.714
B28: 1113308071 | C28: Linares Ortiz Tatiana | D28: FUNDACION VALLE DEL LILI | E28: 2648100 | F28: Ptmo.Ord.No24 | G28: 8600000 | H28: 471 | I28: 0.59 | J28: 0.7 | K28: 18.602972 | L28: 0.7 | M28: C | N28: 2.5334472 | O28: 18.602972 | P28: 0.0227 | Q28: Aportes | R28: 46539000 | S28: 0 | T28: 45315.321
B29: 1116267848 | C29: Salazar Idrobo Laura Daniela | D29: FUNDACION VALLE DEL LILI | E29: 2383300 | F29: Compra Cartera | G29: 5470000 | H29: 835 | I29: 0.05 | J29: 0.13 | K29: 34.578945 | L29: 0.13 | M29: B | N29: 1.9155826 | O29: 34.578945 | P29: 0.0227 | Q29: Aportes | R29: 82352000 | S29: 0 | T29: 45315.325
B30: 1143991760 | C30: Salcedo Rodriguez Nathalia | D30: FUNDACION VALLE DEL LILI | E30: 2320800 | F30: Cred.Ord. Gerencia | G30: 3000000 | H30: 514 | I30: 0.26 | J30: 0.34 | K30: 14.933229 | L30: 0.34 | M30: C | N30: 1.203295 | O30: 14.933229 | P30: 0.0227 | Q30: Aportes | R30: 29399000 | S30: tiene credito afianzadora | T30: 45315.331
B31: 34614231 | C31: Escobar Lopez Giovanna | D31: FUNDACION VALLE DEL LILI - HONORARIOS | E31: 4500000 | F31: Cred.Ord. Gerencia | G31: 4500000 | H31: 621 | I31: 0.66 | J31: 0.7 | K31: 20.910617 | L31: 0.7 | M31: C | N31: 2.2853567 | O31: 20.910617 | P31: 0.0227 | Q31: Aportes | R31: 90984000 | S31: tiene credito afianzadora | T31: 45315.361
B32: 1107081197 | C32: Ramirez Valencia Maria Del Mar | D32: FUNDACION VALLE DEL LILI | E32: 4984600 | F32: Ptmo.Ord.No24 | G32: 5000000 | H32: 677 | I32: 0.33 | J32: 0.39 | K32: 21.378958 | L32: 0.39 | M32: C | N32: 2.0784737 | O32: 21.378958 | P32: 0.0227 | Q32: Aportes | R32: 106367000 | S32: 0 | T32: 45315.369
B33: 94460501 | C33: Bolaños Ceballos John Marlon | D33: FUNDACION VALLE DEL LILI | E33: 4480000 | F33: Ptmo.Ord.No24 | G33: 16700000 | H33: 964 | I33: 0.27 | J33: 0.38 | K33: 2.253233 | L33: 0.38 | M33: A | N33: 0.82431049 | O33: 2.253233 | P33: 0.0199 | Q33: Aportes | R33: 0 | S33: pignora cesantias | T33: 45315.379
B34: 1130675011 | C34: Hidalgo Gomez Diana Maria | D34: FUNDACION VALLE DEL LILI | E34: 2320800 | F34: Ptmo.Ord.No24 | G34: 4000000 | H34: 784 | I34: 0.37 | J34: 0.42 | K34: 27.662929 | L34: 0.42 | M34: C | N34: 1.6895833 | O34: 27.662929 | P34: 0.0227 | Q34: Aportes | R34: 57274000 | S34: pignora cesantias | T34: 45315.386
B35: 60406095 | C35: Prato Hernandez Rosa Margarita | D35: FUNDACION VALLE DEL LILI | E35: 5374700 | F35: Ptmo.Ord.No24 | G35: 4500000 | H35: 665 | I35: 0.34 | J35: 0.38 | K35: 15.355712 | L35: 0.38 | M35: C | N35: 1.3696031 | O35: 15.355712 | P35: 0.0227 | Q35: Aportes | R35: 82352000 | S35: 0 | T35: 45315.393
B36: 1112465080 | C36: Rivas Mora Marlon | D36: FUNDACION VALLE DEL LILI | E36: 2320800 | F36: Cred.Ord. Gerencia | G36: 1700000 | H36: 555 | I36: 0.1 | J36: 0.17 | K36: 2.0667921 | L36: 0.17 | M36: C | N36: 1.2157248 | O36: 2.0667921 | P36: 0.0227 | Q36: Aportes | R36: 3063000 | S36: 0 | T36: 45315.621
B37: 38563522 | C37: Rodriguez Zapata Yaneth Milena | D37: FUNDACION VALLE DEL LILI | E37: 2320800 | F37: Cred.Ord. Gerencia | G37: 1000000 | H37: 608 | I37: 0.35 | J37: 0.37 | K37: 21.311776 | L37: 0.37 | M37: B | N37: 5.1740727 | O37: 21.311776 | P37: 0.0227 | Q37: Aportes | R37: 36616000 | S37: tiene afianzadora | T37: 45316.399
B38: 38873740 | C38: Hernandez Yusti Maria Cristina | D38: FUNDACION VALLE DEL LILI | E38: 2648100 | F38: Cred.Ord. Gerencia | G38: 2700000 | H38: 976 | I38: 0.31 | J38: 0.34 | K38: 2.05838 | L38: 0.34 | M38: B | N38: 0.8689551 | O38: 2.05838 | P38: 0.0227 | Q38: Aportes | R38: 0 | S38: 0 | T38: 45316.507
B39: 1144078618 | C39: Cortes Molina Leydi Vanessa | D39: FUNDACION VALLE DEL LILI | E39: 2320800 | F39: Cred.Ord. Gerencia | G39: 4000000 | H39: 706 | I39: 0.47 | J39: 0.57 | K39: 23.716495 | L39: 0.57 | M39: B | N39: 1.9009863 | O39: 23.716495 | P39: 0.0227 | Q39: Aportes | R39: 47644000 | S39: tiene afianzadora | T39: 45316.566
B40: 1144179107 | C40: Balanta Castellar Kelly Johanna | D40: FUNDACION VALLE DEL LILI | E40: 2648100 | F40: Cred.Ord. Gerencia | G40: 1300000 | H40: 603 | I40: 0.29 | J40: 0.32 | K40: 9.0045776 | L40: 0.32 | M40: C | N40: 1.0203119 | O40: 9.0045776 | P40: 0.0227 | Q40: Aportes | R40: 20498000 | S40: 0 | T40: 45316.575
B41: 16767193 | C41: Gomez Morera Juan Carlos | D41: FUNDACION VALLE DEL LILI | E41: 6946500 | F41: Cred.Ord. Gerencia | G41: 5000000 | H41: 576 | I41: 0.04 | J41: 0.07 | K41: 29.206795 | L41: 0.07 | M41: C | N41: 0.91381142 | O41: 29.206795 | P41: 0.0227 | Q41: Aportes | R41: 202885000 | S41: 0 | T41: 45316.687
...

Sheet Parametros
B2: SMMLV 2024 | C2: 1750905
G3: Tipo de Contrato
B4: Protección de ley SMMLV | G4: Normal | H4: 0.08 | I4: 0
B5: =+$C$2*1 -> 1750905 | C5: =+$C$2*4 -> 7003620 | D5: 0.5 | G5: Integral | H5: 0.7
B6: =+$C$2*4 -> 7003620 | C6: =+$C$2*10 -> 17509050 | D6: 0.4 | G6: Pensionado | H6: 0.12
C7: =+$C$2*10 -> 17509050 | D7: 0.3
G8: Fondo de Solidaridad
B9: Tasa de Usura (Dic 2024) | C9: 0.3498 | D9: =+(1+C9)^(1/12)-1 -> 0.025311398 | G9: =+$C$2*4 -> 7003620 | H9: 0.09
B10: Plazo Tarjetas | D10: 36
G11: Intereses a las cesantias
H12: 0.12
B13: Rango atribuciones
B14: Desde | C14: Hasta | D14: Rango
B15: 0 | C15: 0 | D15: Jefe de Credito y Cartera
B16: 0 | C16: 4000000 | D16: Gerente
B17: 4000000 | C17: 9999999999 | D17: Comité de Credito
B18: 0 | C18: 0 | D18: Consejo de Administración
B20: Nivel de Endeudamiento
B21: Desde | C21: Hasta | D21: Rango
B22: 0 | C22: 15 | D22: Normal
B23: 15 | C23: 20 | D23: Ajustada
B24: > | C24: 20 | D24: Excepción
B26: Desprotegidos - Creditos no Afianzados
B27: Salario | D27: Perfil | E27: Nº SMMLV | F27: Valor Desprotegido | G27: 2023
B28: =+$C$2*$I$28 -> 1750905 | C28: =+$C$2*$J$28 -> 3501810 | D28: A | E28: 5 | F28: =+$C$2*E28 -> 8754525 | G28: 5800000 | I28: 1 | J28: 2
B29: =+$C$2*$I$28 -> 1750905 | C29: =+$C$2*$J$28 -> 3501810 | D29: B | E29: 4 | F29: =+$C$2*E29 -> 7003620 | G29: 4640000
B30: =+$C$2*$I$28 -> 1750905 | C30: =+$C$2*$J$28 -> 3501810 | D30: C | E30: 2 | F30: =+$C$2*E30 -> 3501810 | G30: 2320000
B31: =+$C$2*$I$31+1 -> 3501811 | C31: =+$C$2*$J$31 -> 7003620 | D31: A | E31: 8 | F31: =+$C$2*E31 -> 14007240 | G31: 9280000 | I31: 2 | J31: 4
B32: =+$C$2*$I$31+1 -> 3501811 | C32: =+$C$2*$J$31 -> 7003620 | D32: B | E32: 5 | F32: =+$C$2*E32 -> 8754525 | G32: 5800000
B33: =+$C$2*$I$31+1 -> 3501811 | C33: =+$C$2*$J$31 -> 7003620 | D33: C | E33: 2 | F33: =+$C$2*E33 -> 3501810 | G33: 2320000
B34: =+$C$2*$I$34+1 -> 7003621 | D34: A | E34: 11 | F34: =+$C$2*E34 -> 19259955 | G34: 12760000 | I34: 4
B35: =+$C$2*$I$34+1 -> 7003621 | D35: B | E35: 6 | F35: =+$C$2*E35 -> 10505430 | G35: 6960000
B36: =+$C$2*$I$34+1 -> 7003621 | D36: C | E36: 2 | F36: =+$C$2*E36 -> 3501810 | G36: 2320000
B38: Desprotegidos - Creditos Afianzados
B39: Perfil | C39: Nº SMMLV | D39: Desprotegido | E39: 2023
B40: A | C40: 14 | D40: =+$C$2*C40 -> 24512670 | E40: 18560000 | F40: =+E40-D40 -> -5952670
B41: B | C41: 10 | D41: =+$C$2*C41 -> 17509050 | E41: 12760000 | F41: =+E41-D41 -> -4749050
B44: Analistas | D44: Jefes
B45: Lorena Jimenez | D45: Hugo Fernando Dávila
B46: Diana Martinez | D46: Comité de Credito
...

Sheet Score_Cifin
A1: TIPO_IDENTIFICACION | B1: NUMERO_IDENTIFICACION | C1: CREDITVISION
A2: 1 | B2: 40087405 | C2: 747
A3: 1 | B3: 1144128860 | C3: 794
A4: 1 | B4: 11320970 | C4: 816
A5: 1 | B5: 1130643699 | C5: 632
A6: 1 | B6: 1118282261 | C6: 747
A7: 1 | B7: 66773669 | C7: 784
A8: 1 | B8: 1087118163 | C8: 605
A9: 1 | B9: 38561848 | C9: 557
A10: 1 | B10: 1130595126 | C10: 861
A11: 1 | B11: 31576196 | C11: 910
A12: 1 | B12: 1144067925 | C12: 803
A13: 1 | B13: 1151939688 | C13: 770
... A1782: 1 | B1782: 1144097364 | C1782: 598

Sheet Base_Asociados
B1: COOPERATIVA DE TRABAJODRES DE LA FUNDACIÓN VALLE DEL LILI | L1: =+TODAY() -> 46154 | S1: =+TODAY() -> 46154 | AK1: EMPRESA
B2: BASE DE DATOS ASOCIADOS A JUNIO 2023 | L2: =+_xlfn.DAYS($L$1,L1049)/365 -> 3.1616438 | M2: =+_xlfn.DAYS($L$1,M1049)/365 -> 3.4082192 | AK2: AGRICOLA EL CABUYAL
H3: -1
B4: INFORMACION BASE DE DATOS COOPVALILI | R4: FORMULAS | AK4: AGRODEC
B5: Cedula | C5: apellido | D5: nombre | E5: ciudad | F5: estado civil | G5: Salario | H5: aportes | I5: deuda Coopvalili | J5: edad | K5: Tipo Vivienda | L5: Fecha Ing Coopvalili | M5: Fecha Ing FVL | N5: personas a cargo | O5: Empresa | P5: Nivel | Q5: Cuota Disponible FVL | R5: ASOCIADO | S5: Antigüedad en la Cooperativa | T5: Antigüedad Laboral | U5: Usuario De Credito en Coopvalili | V5: ESTADO_CIVIL
B6: 4661060 | C6: MINA | D6: ROBERTO CARLOS | E6: CALI | F6: Union libre | G6: 2600900 | H6: 3332046 | I6: 7023445 | J6: 43 | K6: 2 | L6: 43654 | M6: 38875 | N6: 1 | O6: FUNDACION VALLE DEL LILI | P6: =VLOOKUP(B6,'NIVEL ENERO'!A:D,3,0) -> 0.39337458 | Q6: =VLOOKUP(B6,'NIVEL ENERO'!A:D,4,0) -> 88218.54 | R6: =+PROPER(C6&" "&D6) -> Mina Roberto Carlos | S6: =+YEARFRAC(L6,$S$1) -> 6.8444444 | T6: =+YEARFRAC(M6,$S$1) -> 19.930556 | U6: =+$I6 -> 7023445 | V6: =+PROPER(F6) -> Union Libre
B7: 4759062 | C7: BALANTA MINA | D7: GENEZAID | E7: CALI | F7: Casado(a) | G7: 2100000 | H7: 13049396 | I7: 0 | J7: 66 | K7: 2 | L7: 39786 | M7: 34350 | N7: 4 | O7: ADMINISTRADOR COLOMBIANA DE PENSIONES | P7: =VLOOKUP(B7,'NIVEL ENERO'!A:D,3,0) -> #N/A | Q7: =VLOOKUP(B7,'NIVEL ENERO'!A:D,4,0) -> #N/A | R7: =+PROPER(C7&" "&D7) -> Balanta Mina Genezaid | S7: =+YEARFRAC(L7,$S$1) -> 17.438889 | T7: =+YEARFRAC(M7,$S$1) -> 32.322222 | U7: =+$I7 -> 0 | V7: =+PROPER(F7) -> Casado(A)
B8: 5208653 | C8: GUERRERO ROSERO | D8: JESUS ORLANDO | E8: CALI | F8: Casado(a) | G8: 8245400 | H8: 3133300 | I8: 0 | J8: 44 | K8: 1 | L8: 43817 | M8: 43452 | N8: 2 | O8: FUNDACION VALLE DEL LILI | P8: =VLOOKUP(B8,'NIVEL ENERO'!A:D,3,0) -> 0.16265461 | Q8: =VLOOKUP(B8,'NIVEL ENERO'!A:D,4,0) -> 2163256.9 | R8: =+PROPER(C8&" "&D8) -> Guerrero Rosero Jesus Orlando | S8: =+YEARFRAC(L8,$S$1) -> 6.4 | T8: =+YEARFRAC(M8,$S$1) -> 7.4 | U8: =+$I8 -> 0 | V8: =+PROPER(F8) -> Casado(A)
B9: 5824652 | C9: CARVAJAL JIMENEZ | D9: CARLOS ANDRES | E9: CALI | F9: Soltero(a) | G9: 2089800 | H9: 5329875 | I9: 7507873 | J9: 43 | K9: 2 | L9: 43817 | M9: 40344 | N9: 3 | O9: FUNDACION VALLE DEL LILI | P9: =VLOOKUP(B9,'NIVEL ENERO'!A:D,3,0) -> 0.48223088 | Q9: =VLOOKUP(B9,'NIVEL ENERO'!A:D,4,0) -> -222943 | R9: =+PROPER(C9&" "&D9) -> Carvajal Jimenez Carlos Andres | S9: =+YEARFRAC(L9,$S$1) -> 6.4 | T9: =+YEARFRAC(M9,$S$1) -> 15.908333 | U9: =+$I9 -> 7507873 | V9: =+PROPER(F9) -> Soltero(A)
B10: 6098612 | C10: TORO GARCIA | D10: JOHN FABIO | E10: CALI | F10: Casado(a) | G10: 1625000 | H10: 1180060 | I10: 95250 | J10: 45 | K10: 1 | L10: 45096 | M10: 44964 | N10: 0 | O10: FUNDACION VALLE DEL LILI | P10: =VLOOKUP(B10,'NIVEL ENERO'!A:D,3,0) -> 0.4019979 | Q10: =VLOOKUP(B10,'NIVEL ENERO'!A:D,4,0) -> 69651 | R10: =+PROPER(C10&" "&D10) -> Toro Garcia John Fabio | S10: =+YEARFRAC(L10,$S$1) -> 2.8972222 | T10: =+YEARFRAC(M10,$S$1) -> 3.2638889 | U10: =+$I10 -> 95250 | V10: =+PROPER(F10) -> Casado(A)
B11: 6135820 | C11: ROJAS GARCIA | D11: ALEXANDER | E11: CALI | F11: Soltero(a) | G11: 8245400 | H11: 7465998 | I11: 2911197 | J11: 43 | K11: 1 | L11: 42074 | M11: 42065 | N11: 2 | O11: FUNDACION VALLE DEL LILI | P11: =VLOOKUP(B11,'NIVEL ENERO'!A:D,3,0) -> 0.25286194 | Q11: =VLOOKUP(B11,'NIVEL ENERO'!A:D,4,0) -> 1408205 | R11: =+PROPER(C11&" "&D11) -> Rojas Garcia Alexander | S11: =+YEARFRAC(L11,$S$1) -> 11.169444 | T11: =+YEARFRAC(M11,$S$1) -> 11.194444 | U11: =+$I11 -> 2911197 | V11: =+PROPER(F11) -> Soltero(A)
B12: 6199680 | C12: GOMEZ GRISALES | D12: ALVARO HERNAN | E12: CALI | F12: Casado(a) | G12: 6247700 | H12: 3492610 | I12: 0 | J12: 44 | K12: 6 | L12: 43333 | M12: 40554 | N12: 4 | O12: FUNDACION VALLE DEL LILI | P12: =VLOOKUP(B12,'NIVEL ENERO'!A:D,3,0) -> 0.37801436 | Q12: =VLOOKUP(B12,'NIVEL ENERO'!A:D,4,0) -> 315230.64 | R12: =+PROPER(C12&" "&D12) -> Gomez Grisales Alvaro Hernan | S12: =+YEARFRAC(L12,$S$1) -> 7.725 | T12: =+YEARFRAC(M12,$S$1) -> 15.336111 | U12: =+$I12 -> 0 | V12: =+PROPER(F12) -> Casado(A)
B13: 6355880 | C13: MONDRAGON GORDILLO | D13: FERNELLY | E13: CALI | F13: Casado(a) | G13: 2298000 | H13: 5711566 | I13: 0 | J13: 68 | K13: 2 | L13: 41733 | M13: 41733 | N13: 2 | O13: ADMINISTRADOR COLOMBIANA DE PENSIONES | P13: =VLOOKUP(B13,'NIVEL ENERO'!A:D,3,0) -> #N/A | Q13: =VLOOKUP(B13,'NIVEL ENERO'!A:D,4,0) -> #N/A | R13: =+PROPER(C13&" "&D13) -> Mondragon Gordillo Fernelly | S13: =+YEARFRAC(L13,$S$1) -> 12.105556 | T13: =+YEARFRAC(M13,$S$1) -> 12.105556 | U13: =+$I13 -> 0 | V13: =+PROPER(F13) -> Casado(A)
B14: 6391199 | C14: ANDRADE BLANCO | D14: LUIS FERNANDO | E14: CALI | F14: Casado(a) | G14: 2916600 | H14: 4613628 | I14: 3516540 | J14: 43 | K14: 4 | L14: 44636 | M14: 40436 | N14: 4 | O14: FUNDACION VALLE DEL LILI | P14: =VLOOKUP(B14,'NIVEL ENERO'!A:D,3,0) -> 0.35000198 | Q14: =VLOOKUP(B14,'NIVEL ENERO'!A:D,4,0) -> 276853.6 | R14: =+PROPER(C14&" "&D14) -> Andrade Blanco Luis Fernando | S14: =+YEARFRAC(L14,$S$1) -> 4.1555556 | T14: =+YEARFRAC(M14,$S$1) -> 15.658333 | U14: =+$I14 -> 3516540 | V14: =+PROPER(F14) -> Casado(A)
B15: 6393613 | C15: TORO CORREA | D15: JOSE JOAQUIN | E15: CALI | F15: Union libre | G15: 18113200 | H15: 3444817 | I15: 61558704 | J15: 43 | K15: 4 | L15: 45096 | M15: 42121 | N15: 0 | O15: FUNDACION VALLE DEL LILI | P15: =VLOOKUP(B15,'NIVEL ENERO'!A:D,3,0) -> 0.38388767 | Q15: =VLOOKUP(B15,'NIVEL ENERO'!A:D,4,0) -> 755956.4 | R15: =+PROPER(C15&" "&D15) -> Toro Correa Jose Joaquin | S15: =+YEARFRAC(L15,$S$1) -> 2.8972222 | T15: =+YEARFRAC(M15,$S$1) -> 11.041667 | U15: =+$I15 -> 61558704 | V15: =+PROPER(F15) -> Union Libre
B16: 6537914 | C16: DELGADO ALVAREZ | D16: ALEXIS | E16: FLORIDA | F16: Soltero(a) | G16: 8245400 | H16: 2011731 | I16: 3143167 | J16: 44 | K16: 2 | L16: 44579 | M16: 40148 | N16: 4 | O16: FUNDACION VALLE DEL LILI | P16: =VLOOKUP(B16,'NIVEL ENERO'!A:D,3,0) -> 0.1642021 | Q16: =VLOOKUP(B16,'NIVEL ENERO'!A:D,4,0) -> 2109156 | R16: =+PROPER(C16&" "&D16) -> Delgado Alvarez Alexis | S16: =+YEARFRAC(L16,$S$1) -> 4.3166667 | T16: =+YEARFRAC(M16,$S$1) -> 16.447222 | U16: =+$I16 -> 3143167 | V16: =+PROPER(F16) -> Soltero(A)
B17: 6550905 | C17: VIDAL BUENO | D17: JORGE HERNAN | E17: CALI | F17: Union libre | G17: 4870200 | H17: 1600537 | I17: 1389409 | J17: 40 | K17: 3 | L17: 45191 | M17: 41593 | N17: 0 | O17: FUNDACION VALLE DEL LILI | P17: =VLOOKUP(B17,'NIVEL ENERO'!A:D,3,0) -> 0.35995955 | Q17: =VLOOKUP(B17,'NIVEL ENERO'!A:D,4,0) -> 391637.36 | R17: =+PROPER(C17&" "&D17) -> Vidal Bueno Jorge Hernan | S17: =+YEARFRAC(L17,$S$1) -> 2.6388889 | T17: =+YEARFRAC(M17,$S$1) -> 12.491667 | U17: =+$I17 -> 1389409 | V17: =+PROPER(F17) -> Union Libre
B18: 9292583 | C18: LAMBRANO BARRERA | D18: RAFAEL ARMANDO | E18: CALI | F18: Casado(a) | G18: 5679200 | H18: 2304741 | J18: 47 | K18: 1 | L18: 44977 | M18: 40954 | N18: 0 | O18: FUNDACION VALLE DEL LILI | P18: =VLOOKUP(B18,'NIVEL ENERO'!A:D,3,0) -> 0.26760543 | Q18: =VLOOKUP(B18,'NIVEL ENERO'!A:D,4,0) -> 1461723 | R18: =+PROPER(C18&" "&D18) -> Lambrano Barrera Rafael Armando | S18: =+YEARFRAC(L18,$S$1) -> 3.2277778 | T18: =+YEARFRAC(M18,$S$1) -> 14.241667 | U18: =+$I18 -> 0 | V18: =+PROPER(F18) -> Casado(A)
B19: 10280915 | C19: TRUJILLO ARANGO | D19: GERMAN HUMBERTO | E19: CALI | F19: Casado(a) | G19: 19690900 | H19: 5133080 | I19: 3963132 | J19: 56 | K19: 6 | L19: 37987 | M19: 36913 | N19: 2 | O19: FUNDACION VALLE DEL LILI | P19: =VLOOKUP(B19,'NIVEL ENERO'!A:D,3,0) -> 0.47565441 | Q19: =VLOOKUP(B19,'NIVEL ENERO'!A:D,4,0) -> -1187939.9 | R19: =+PROPER(C19&" "&D19) -> Trujillo Arango German Humberto | S19: =+YEARFRAC(L19,$S$1) -> 22.363889 | T19: =+YEARFRAC(M19,$S$1) -> 25.305556 | U19: =+$I19 -> 3963132 | V19: =+PROPER(F19) -> Casado(A)
B20: 10285994 | C20: CORREA GARCIA | D20: ORLANDO | E20: CALI | F20: Union libre | G20: 5418800 | H20: 21421217 | I20: 0 | J20: 55 | K20: 1 | L20: 40076 | M20: 40066 | N20: 3 | O20: FUNDACION VALLE DEL LILI | P20: =VLOOKUP(B20,'NIVEL ENERO'!A:D,3,0) -> 0.17595909 | Q20: =VLOOKUP(B20,'NIVEL ENERO'!A:D,4,0) -> 1861721.8 | R20: =+PROPER(C20&" "&D20) -> Correa Garcia Orlando | S20: =+YEARFRAC(L20,$S$1) -> 16.644444 | T20: =+YEARFRAC(M20,$S$1) -> 16.672222 | U20: =+$I20 -> 0 | V20: =+PROPER(F20) -> Union Libre
B21: 10294212 | C21: HURTADO PABON | D21: HARRY FABIAN | E21: CALI | F21: Union libre | G21: 4469100 | H21: 2570104 | I21: 1152580 | J21: 42 | K21: 2 | L21: 44579 | M21: 44155 | N21: 4 | O21: FUNDACION VALLE DEL LILI | P21: =VLOOKUP(B21,'NIVEL ENERO'!A:D,3,0) -> 0.15254105 | Q21: =VLOOKUP(B21,'NIVEL ENERO'!A:D,4,0) -> 1642759 | R21: =+PROPER(C21&" "&D21) -> Hurtado Pabon Harry Fabian | S21: =+YEARFRAC(L21,$S$1) -> 4.3166667 | T21: =+YEARFRAC(M21,$S$1) -> 5.4777778 | U21: =+$I21 -> 1152580 | V21: =+PROPER(F21) -> Union Libre
B22: 10567677 | C22: ORDONEZ PALECHOR | D22: MARIO GENTIL | E22: JAMUNDÍ | F22: Union libre | G22: 1670000 | H22: 2420842 | I22: 1112457 | J22: 45 | K22: 2 | L22: 44274 | M22: 42787 | N22: 3 | O22: FUNDACION VALLE DEL LILI | P22: =VLOOKUP(B22,'NIVEL ENERO'!A:D,3,0) -> 0.36013304 | Q22: =VLOOKUP(B22,'NIVEL ENERO'!A:D,4,0) -> 131217.3 | R22: =+PROPER(C22&" "&D22) -> Ordonez Palechor Mario Gentil | S22: =+YEARFRAC(L22,$S$1) -> 5.1472222 | T22: =+YEARFRAC(M22,$S$1) -> 9.225 | U22: =+$I22 -> 1112457 | V22: =+PROPER(F22) -> Union Libre
B23: 10723755 | C23: HURTADO HURTADO | D23: JOHN JAMES | E23: CALI | F23: Soltero(a) | G23: 4870200 | H23: 1300011 | J23: 39 | K23: 2 | L23: 45279 | M23: 41074 | N23: 0 | O23: FUNDACION VALLE DEL LILI | P23: =VLOOKUP(B23,'NIVEL ENERO'!A:D,3,0) -> 0.22224371 | Q23: =VLOOKUP(B23,'NIVEL ENERO'!A:D,4,0) -> 1086921.6 | R23: =+PROPER(C23&" "&D23) -> Hurtado Hurtado John James | S23: =+YEARFRAC(L23,$S$1) -> 2.3972222 | T23: =+YEARFRAC(M23,$S$1) -> 13.911111 | U23: =+$I23 -> 0 | V23: =+PROPER(F23) -> Soltero(A)
B24: 11320970 | C24: HERNANDEZ CHAVEZ | D24: CARLOS HOLMES | E24: CALI | F24: Union libre | G24: 5374700 | H24: 3298561 | I24: 0 | J24: 52 | K24: 4 | L24: 43627 | M24: 34821 | N24: 4 | O24: FUNDACION VALLE DEL LILI | P24: =VLOOKUP(B24,'NIVEL ENERO'!A:D,3,0) -> 0.42754621 | Q24: =VLOOKUP(B24,'NIVEL ENERO'!A:D,4,0) -> -56033.88 | R24: =+PROPER(C24&" "&D24) -> Hernandez Chavez Carlos Holmes | S24: =+YEARFRAC(L24,$S$1) -> 6.9194444 | T24: =+YEARFRAC(M24,$S$1) -> 31.027778 | U24: =+$I24 -> 0 | V24: =+PROPER(F24) -> Union Libre
B25: 11620559 | C25: MOSQUERA PALACIO | D25: EVIS JOTH | E25: CALI | F25: Union libre | G25: 2600900 | H25: 905339 | I25: 1430597 | J25: 45 | K25: 1 | L25: 45370 | M25: 44781 | N25: 1 | O25: FUNDACION VALLE DEL LILI | P25: =VLOOKUP(B25,'NIVEL ENERO'!A:D,3,0) -> 0.3896538 | Q25: =VLOOKUP(B25,'NIVEL ENERO'!A:D,4,0) -> 81558.32 | R25: =+PROPER(C25&" "&D25) -> Mosquera Palacio Evis Joth | S25: =+YEARFRAC(L25,$S$1) -> 2.1472222 | T25: =+YEARFRAC(M25,$S$1) -> 3.7611111 | U25: =+$I25 -> 1430597 | V25: =+PROPER(F25) -> Union Libre
B26: 11830463 | C26: HINESTROZA GAMBOA | D26: CELIMO | E26: CALI | F26: Union libre | G26: 1918500 | H26: 3682544 | I26: 4123050 | J26: 54 | K26: 4 | L26: 43392 | M26: 43200 | N26: 4 | O26: FUNDACION VALLE DEL LILI | P26: =VLOOKUP(B26,'NIVEL ENERO'!A:D,3,0) -> 0.40318424 | Q26: =VLOOKUP(B26,'NIVEL ENERO'!A:D,4,0) -> 76812 | R26: =+PROPER(C26&" "&D26) -> Hinestroza Gamboa Celimo | S26: =+YEARFRAC(L26,$S$1) -> 7.5638889 | T26: =+YEARFRAC(M26,$S$1) -> 8.0888889 | U26: =+$I26 -> 4123050 | V26: =+PROPER(F26) -> Union Libre
B27: 13069223 | C27: JOJOA HERNANDEZ | D27: MILTON ALEXANDER | E27: CALI | F27: Casado(a) | G27: 13588800 | H27: 6790485 | I27: 614601 | J27: 46 | K27: 2 | L27: 44245 | M27: 41075 | N27: 3 | O27: FUNDACION VALLE DEL LILI | P27: =VLOOKUP(B27,'NIVEL ENERO'!A:D,3,0) -> 0.22942232 | Q27: =VLOOKUP(B27,'NIVEL ENERO'!A:D,4,0) -> 2589722 | R27: =+PROPER(C27&" "&D27) -> Jojoa Hernandez Milton Alexander | S27: =+YEARFRAC(L27,$S$1) -> 5.2333333 | T27: =+YEARFRAC(M27,$S$1) -> 13.908333 | U27: =+$I27 -> 614601 | V27: =+PROPER(F27) -> Casado(A)
B28: 14465776 | C28: CANAMEJOY GARCIA | D28: JUAN PABLO | E28: CALI | F28: Soltero(a) | G28: 3945300 | H28: 4411459 | I28: 2352123 | J28: 42 | K28: 1 | L28: 44328 | M28: 40238 | N28: 4 | O28: FUNDACION VALLE DEL LILI | P28: =VLOOKUP(B28,'NIVEL ENERO'!A:D,3,0) -> 0.46233948 | Q28: =VLOOKUP(B28,'NIVEL ENERO'!A:D,4,0) -> -188224.8 | R28: =+PROPER(C28&" "&D28) -> Canamejoy Garcia Juan Pablo | S28: =+YEARFRAC(L28,$S$1) -> 5 | T28: =+YEARFRAC(M28,$S$1) -> 16.197222 | U28: =+$I28 -> 2352123 | V28: =+PROPER(F28) -> Soltero(A)
B29: 14479754 | C29: ANGULO SEGURA | D29: ARVEY | E29: CALI | F29: Soltero(a) | G29: 1625000 | H29: 1910716 | I29: 5827259 | J29: 40 | K29: 2 | L29: 44635 | M29: 44099 | N29: 0 | O29: FUNDACION VALLE DEL LILI | P29: =VLOOKUP(B29,'NIVEL ENERO'!A:D,3,0) -> 0.36114628 | Q29: =VLOOKUP(B29,'NIVEL ENERO'!A:D,4,0) -> 129546.98 | R29: =+PROPER(C29&" "&D29) -> Angulo Segura Arvey | S29: =+YEARFRAC(L29,$S$1) -> 4.1583333 | T29: =+YEARFRAC(M29,$S$1) -> 5.6305556 | U29: =+$I29 -> 5827259 | V29: =+PROPER(F29) -> Soltero(A)
B30: 14590768 | C30: LLOREDA MEJIA | D30: LUIS FRANCISCO | E30: CALI | F30: Separado(a) | G30: 5418800 | H30: 3476448 | I30: 10166088 | J30: 42 | K30: 2 | L30: 44155 | M30: 39756 | N30: 2 | O30: FUNDACION VALLE DEL LILI | P30: =VLOOKUP(B30,'NIVEL ENERO'!A:D,3,0) -> 0.26518277 | Q30: =VLOOKUP(B30,'NIVEL ENERO'!A:D,4,0) -> 1231980.9 | R30: =+PROPER(C30&" "&D30) -> Lloreda Mejia Luis Francisco | S30: =+YEARFRAC(L30,$S$1) -> 5.4777778 | T30: =+YEARFRAC(M30,$S$1) -> 17.522222 | U30: =+$I30 -> 10166088 | V30: =+PROPER(F30) -> Separado(A)
B31: 14607266 | C31: RAMOS LASSO | D31: JULIAN | E31: CALI | F31: Union libre | G31: 5418800 | H31: 4414912 | I31: 4045957 | J31: 42 | K31: 1 | L31: 45051 | M31: 40589 | N31: 4 | O31: FUNDACION VALLE DEL LILI | P31: =VLOOKUP(B31,'NIVEL ENERO'!A:D,3,0) -> 0.17074916 | Q31: =VLOOKUP(B31,'NIVEL ENERO'!A:D,4,0) -> 1794590.1 | R31: =+PROPER(C31&" "&D31) -> Ramos Lasso Julian | S31: =+YEARFRAC(L31,$S$1) -> 3.0194444 | T31: =+YEARFRAC(M31,$S$1) -> 15.241667 | U31: =+$I31 -> 4045957 | V31: =+PROPER(F31) -> Union Libre
B32: 14608276 | C32: MEZA TORRES | D32: EDWAR ERNESTO | E32: CALI | F32: Casado(a) | G32: 2600900 | H32: 1015322 | J32: 41 | K32: 1 | L32: 45191 | M32: 44365 | N32: 0 | O32: FUNDACION VALLE DEL LILI | P32: =VLOOKUP(B32,'NIVEL ENERO'!A:D,3,0) -> 0.11933907 | Q32: =VLOOKUP(B32,'NIVEL ENERO'!A:D,4,0) -> 781989 | R32: =+PROPER(C32&" "&D32) -> Meza Torres Edwar Ernesto | S32: =+YEARFRAC(L32,$S$1) -> 2.6388889 | T32: =+YEARFRAC(M32,$S$1) -> 4.9 | U32: =+$I32 -> 0 | V32: =+PROPER(F32) -> Casado(A)
B33: 14608714 | C33: DIAZ MENESES | D33: DAVID ORLANDO | E33: CALI | F33: Union libre | G33: 5418800 | H33: 15238115 | I33: 12143696 | J33: 41 | K33: 1 | L33: 40526 | M33: 39756 | N33: 4 | O33: FUNDACION VALLE DEL LILI | P33: =VLOOKUP(B33,'NIVEL ENERO'!A:D,3,0) -> 0.18836387 | Q33: =VLOOKUP(B33,'NIVEL ENERO'!A:D,4,0) -> 1768999.1 | R33: =+PROPER(C33&" "&D33) -> Diaz Meneses David Orlando | S33: =+YEARFRAC(L33,$S$1) -> 15.411111 | T33: =+YEARFRAC(M33,$S$1) -> 17.522222 | U33: =+$I33 -> 12143696 | V33: =+PROPER(F33) -> Union Libre
B34: 14609734 | C34: MONTANO PRECIADO | D34: JHON FREDDY | E34: CALI | F34: Union libre | G34: 1625000 | H34: 2283663 | I34: 2187024 | J34: 40 | K34: 2 | L34: 44398 | M34: 44175 | N34: 3 | O34: FUNDACION VALLE DEL LILI | P34: =VLOOKUP(B34,'NIVEL ENERO'!A:D,3,0) -> 0.27381485 | Q34: =VLOOKUP(B34,'NIVEL ENERO'!A:D,4,0) -> 316837.8 | R34: =+PROPER(C34&" "&D34) -> Montano Preciado Jhon Freddy | S34: =+YEARFRAC(L34,$S$1) -> 4.8083333 | T34: =+YEARFRAC(M34,$S$1) -> 5.4222222 | U34: =+$I34 -> 2187024 | V34: =+PROPER(F34) -> Union Libre
B35: 14621610 | C35: MUNOZ VALERO | D35: ALVARO | E35: CALI | F35: Soltero(a) | G35: 4761900 | H35: 6363376 | I35: 0 | J35: 41 | K35: 1 | L35: 42871 | M35: 37043 | N35: 1 | O35: FUNDACION VALLE DEL LILI | P35: =VLOOKUP(B35,'NIVEL ENERO'!A:D,3,0) -> 0.22452655 | Q35: =VLOOKUP(B35,'NIVEL ENERO'!A:D,4,0) -> 930825 | R35: =+PROPER(C35&" "&D35) -> Munoz Valero Alvaro | S35: =+YEARFRAC(L35,$S$1) -> 8.9888889 | T35: =+YEARFRAC(M35,$S$1) -> 24.947222 | U35: =+$I35 -> 0 | V35: =+PROPER(F35) -> Soltero(A)
B36: 14638297 | C36: ARANGO NARVAEZ | D36: OSCAR EDUARDO | E36: CALI | F36: Union libre | G36: 5418800 | H36: 3718870 | I36: 1898217 | J36: 40 | K36: 1 | L36: 44519 | M36: 44393 | N36: 4 | O36: FUNDACION VALLE DEL LILI | P36: =VLOOKUP(B36,'NIVEL ENERO'!A:D,3,0) -> 0.38992453 | Q36: =VLOOKUP(B36,'NIVEL ENERO'!A:D,4,0) -> 221501.52 | R36: =+PROPER(C36&" "&D36) -> Arango Narvaez Oscar Eduardo | S36: =+YEARFRAC(L36,$S$1) -> 4.4805556 | T36: =+YEARFRAC(M36,$S$1) -> 4.8222222 | U36: =+$I36 -> 1898217 | V36: =+PROPER(F36) -> Union Libre
B37: 14638857 | C37: OCAMPO GALLEGO | D37: JONNATHAN | E37: CALI | F37: Union libre | G37: 5418800 | H37: 1256457 | I37: 375780 | J37: 40 | K37: 6 | L37: 45064 | M37: 40988 | N37: 2 | O37: FUNDACION VALLE DEL LILI | P37: =VLOOKUP(B37,'NIVEL ENERO'!A:D,3,0) -> 0.32302269 | Q37: =VLOOKUP(B37,'NIVEL ENERO'!A:D,4,0) -> 530831.8 | R37: =+PROPER(C37&" "&D37) -> Ocampo Gallego Jonnathan | S37: =+YEARFRAC(L37,$S$1) -> 2.9833333 | T37: =+YEARFRAC(M37,$S$1) -> 14.144444 | U37: =+$I37 -> 375780 | V37: =+PROPER(F37) -> Union Libre
B38: 14797927 | C38: WAGNER DIAZ | D38: JULIO ENRIQUE | E38: CALI | F38: Union libre | G38: 2600900 | H38: 5292123 | I38: 1522898 | J38: 42 | K38: 1 | L38: 42191 | M38: 42139 | N38: 2 | O38: FUNDACION VALLE DEL LILI | P38: =VLOOKUP(B38,'NIVEL ENERO'!A:D,3,0) -> 0.29916337 | Q38: =VLOOKUP(B38,'NIVEL ENERO'!A:D,4,0) -> 314284 | R38: =+PROPER(C38&" "&D38) -> Wagner Diaz Julio Enrique | S38: =+YEARFRAC(L38,$S$1) -> 10.85 | T38: =+YEARFRAC(M38,$S$1) -> 10.991667 | U38: =+$I38 -> 1522898 | V38: =+PROPER(F38) -> Union Libre
B39: 14837964 | C39: NINO MOTATO | D39: HUGO FERNANDO | E39: CALI | F39: Casado(a) | G39: 2893800 | H39: 2249657 | I39: 2462396 | J39: 44 | K39: 2 | L39: 44669 | M39: 39118 | N39: 3 | O39: FUNDACION VALLE DEL LILI | P39: =VLOOKUP(B39,'NIVEL ENERO'!A:D,3,0) -> 0.36386528 | Q39: =VLOOKUP(B39,'NIVEL ENERO'!A:D,4,0) -> 223252.68 | R39: =+PROPER(C39&" "&D39) -> Nino Motato Hugo Fernando | S39: =+YEARFRAC(L39,$S$1) -> 4.0666667 | T39: =+YEARFRAC(M39,$S$1) -> 19.269444 | U39: =+$I39 -> 2462396 | V39: =+PROPER(F39) -> Casado(A)
B40: 14839121 | C40: URIBE PAZ | D40: HARVIN RICARDO | E40: CALI | F40: Casado(a) | G40: 1918500 | H40: 1864687 | I40: 0 | J40: 44 | K40: 1 | L40: 45051 | M40: 44378 | N40: 0 | O40: FUNDACION VALLE DEL LILI | P40: =VLOOKUP(B40,'NIVEL ENERO'!A:D,3,0) -> 0.49502686 | Q40: =VLOOKUP(B40,'NIVEL ENERO'!A:D,4,0) -> -342712 | R40: =+PROPER(C40&" "&D40) -> Uribe Paz Harvin Ricardo | S40: =+YEARFRAC(L40,$S$1) -> 3.0194444 | T40: =+YEARFRAC(M40,$S$1) -> 4.8638889 | U40: =+$I40 -> 0 | V40: =+PROPER(F40) -> Casado(A)
...

Sheet Capacidad_Endeudamiento
A1: cedula | B1: COOPERATIVA DE TRABAJADORES DE LA FUNDACIÓN VALLE DEL LILI | O1: =+IF(Datos_Iniciales!C8=2,(Capacidad_Endeudamiento!$C$25*Parametros!$H$5),Capacidad_Endeudamiento!$C$25) -> 2500000
B2: MODELO ASIGNACIÓN DE CRÉDITOS | O2: =IF($C$25>Parametros!$G$9,Parametros!$H$9,Parametros!$H$4) -> 0.08 | V2: N° CEDULA | W2: ASOCIADO | X2: EMPRESA | Y2: SALARIO | Z2: LÍNEA DE CRÉDITO | AA2: MONTO SOLICITADO | AB2: SCOR CIFIN | AC2: ENDEUDAMIENTO ACTUAL | AD2: ENDEUDAMIENTO PROYECTADO | AE2: CME | AF2: CMD | AG2: PERFIL | AH2: SOLVENCIA | AI2: NIVEL_EDEUDAMIENTO | AJ2: TASA | AK2: GARANTIA | AL2: DEUDA SECTOR | AM2: OBSERVACIONES | AN2: FECHA
B3: =+TODAY() -> 46154 | C3: Solicitud N° | V3: =+$C$11 -> 1112878165 | W3: =+$C$12 -> Varon Barrios Yina Marcela | X3: =+$C$13 -> FUNDACION VALLE DEL LILI | Y3: =+$C$25 -> 2500000 | Z3: =+$C$60 -> Cred.Ord. Gerencia | AA3: =+$C$61 -> 4000000 | AB3: =+$C$31 -> 657 | AC3: =+$C$84 -> 0.26 | AD3: =+$C$86 -> 0.35 | AE3: =+#REF! -> #REF! | AF3: =+$C$7 -> 0.35 | AG3: =+$C$5 -> C | AH3: =+$C$93 -> 0.39843807 | AI3: =+#REF! -> #REF! | AJ3: =+$C$64 -> 0.011040394 | AK3: =+$C$8 -> Aportes | AL3: =+$C$17 -> 0 | AM3: =+$B$114 -> 0 | AN3: =+NOW() -> 46154.724
B5: PERFIL | C5: =+'Base Perfil'!$V$4 -> C | D5: Calculo Motor | O5: =+$C$25-($O$2*$O$1) -> 2300000
B6: VALOR DESPROTEGIDO MAX DE LA LINEA | C6: =+IF(Datos_Iniciales!$C$4=1,IF($C$5=Parametros!$B$40,Parametros!$D$40,IF($C$5=Parametros!$B$41,Parametros!$D$41)),IF(AND($C$5=Parametros!$D$28,$C$37>=Parametros!$B$28,$C$37<=Parametros!$C$28),Parametros!$F$28,IF(AND($C$5=Parametros!$D$29,$C$37>=Parametros!$B$29,$C$37<=Parametros!$C$29),Parametros!$F$29,IF(AND($C$5=Parametros!$D$30,$C$37>=Parametros!$B$30,$C$37<=Parametros!$C$30),Parametros!$F$30,IF(AND($C$5=Parametros!$D$31,$C$37>=Parametros!$B$31,$C$37<=Parametros!$C$31),Parametros!$F$31,IF(AND($C$5=Parametros!$D$32,$C$37>=Parametros!$B$32,$C$37<=Parametros!$C$32),Parametros!$F$32,IF(AND($C$5=Parametros!$D$33,$C$37>=Parametros!$B$33,$C$37<=Parametros!$C$33),Parametros!$F$33,IF(AND($C$5=Parametros!$D$34,$C$37>=Parametros!$B$34),Parametros!$F$34,IF(AND($C$5=Parametros!$D$35,$C$37>=Parametros!$B$35),Parametros!$F$35,IF(AND($C$5=Parametros!$D$36,$C$37>=Parametros!$B$36),Parametros!$F$36,"N/A")))))))))) -> 3501810 | D6: Calculo Motor
B7: =+$O$7&" "&$O$9 -> VIABLE CMD | C7: =+IFERROR(MROUND(($C$75+$C$28-C20)/$O$5,1%),"") -> 0.35 | D7: Calculo Motor | O7: =+IF(C7>51%,"NO VIABLE","VIABLE") -> VIABLE | V7: Nota: | W7: =+IF($C$8="","FALTA "&$B$8,IF($C$64="","FALTA TASA DE INTERES",""))
B8: GARANTÍA | C8: Aportes | D8: Parámetro | L8: Credito | M8: =+VLOOKUP(Datos_Iniciales!$E$13,Datos_Iniciales!$Q$10:$R$12,2,FALSE()) -> Mensual
L9: Monto | M9: =+$C$61 -> 4000000 | O9: CMD
L10: Intereses Anual | M10: =+$C$64*12 -> 0.13248473
B11: N° Cedula | C11: 1112878165 | L11: Tiempo en Años | M11: =+$C$30 -> 1
A12: "primer_apellido"&"segundo_apellido": "BARRIOS"&"nombre": "YINA MARCELA", | B12: Asociado | C12: =+INDEX(Base_Asociados!$B$6:$V$9877,MATCH($C$11,Base_Asociados!$B$6:$B$9877,0),MATCH($B12,Base_Asociados!$B$5:$V$5,0)) -> Varon Barrios Yina Marcela | D12: API | L12: Pagos Anuales | M12: =+IF(Datos_Iniciales!$E$13=1,Datos_Iniciales!$S$10,IF(Datos_Iniciales!$E$13=2,Datos_Iniciales!$S$11,Datos_Iniciales!$S$12)) -> 12
A13: cliente_empresa | B13: Empresa | C13: =+INDEX(Base_Asociados!$B$6:$V$9877,MATCH($C$11,Base_Asociados!$B$6:$B$9877,0),MATCH($B13,Base_Asociados!$B$5:$V$5,0)) -> FUNDACION VALLE DEL LILI | D13: API | L13: Cuota | M13: =-PMT(M10/M12,M11*M12,M9) -> 357735.57
A14: saldo_fecha | B14: Aportes | C14: 3500000 | D14: API | L14: Cuota_Frecuencia | M14: =+IF(M8="Semanal",($M$13*$M$12)/12,IF(M8="Quincenal",M13*2,M13)) -> 357735.57
A15: SaldoCapital | B15: Deuda Coopvalili | C15: 2500671 | D15: API
B16: Cupo Rotativo
A17: Deuda <> TC y Coopvalili | B17: Deuda Sector | C17: 0 | D17: TU
A18: Deuda de tarjetas en TU | B18: Cupos TDC | C18: 4258000 | D18: TU | O18: SI
B19: Cuota TDC | C19: =+Datos_Iniciales!$E$18 -> 181631.4 | D19: Calculo Motor | O19: NO
A20: Cuota_fecha + ValorCuotaFija | B20: Cuota que Recoge Coopvalili | D20: API
B21: Cuota que Recoge Sector | D21: TU
O22: Normal
C24: =+Datos_Iniciales!$C$8 -> 1 | O24: Integral
B25: Salario | C25: 2500000 | D25: Chat | E25: No se si es Chat o Base_Asociados | O25: Pensionado
B26: Otros Ingresos | D26: No aplica
B27: Descuentos de Ley | C27: =+IF(AND($C$24=1,$C$25>Parametros!$G$9),$C$25*Parametros!$H$9,IF(AND($C$24=1,$C$25<=Parametros!$G$9),$C$25*Parametros!$H$4,IF(AND($C$24=2,$C$25>Parametros!$G$9),($C$25*Parametros!$H$5)*Parametros!$H$9,IF(AND($C$24=2,$C$25<=Parametros!$G$9),($C$25*Parametros!$H$5)*Parametros!$H$4,IF($C$24=3,$C$25*Parametros!$H$6))))) -> 200000 | D27: Cálculo Motor
B28: Egresos Volante de Pago | C28: 600000 | D28: Chat | E28: No se si es Chat o Base_Asociados
B29: Egresos Cuotas Sector | C29: 0 | D29: TU
B30: Plazo | C30: 1 | D30: No aplica
B31: Scor Cifin | C31: 657 | D31: TU
B32: Tasa Interés Efectiva | C32: 0.3015 | D32: Parámetro
A33: frecuencia | B33: Frecuencia de Pagos | C33: quincenal | D33: Chat
A34: frecuencia_mes | B34: Frecuencia mes | C34: =IF(C33="semanal",4,IF(C33="quincenal",2,IF(C33="mensual",1,"Revisar"))) -> 2 | D34: Cálculo Motor
B37: Ingresos | C37: =+$C$25 -> 2500000 | D37: Cálculo Motor | E37: Este cálculo implicitamente es mensual
B38: Mínimo Vital | C38: =+IF(AND(C25>=Parametros!$B$5,C25<=Parametros!$C$5),$C$25*Parametros!$D$5,IF(AND(C25>Parametros!$C$5,C25<=Parametros!$C$6),$C$25*Parametros!$D$6,IF(C25>Parametros!$C$7,$C$25*Parametros!D7))) -> 1250000 | D38: Cálculo Motor
B39: Egresos | C39: =+($C$28+$C$29+C19-C20-C21)-($C$26/2) -> 781631.4 | D39: Cálculo Motor
A40: cuota_max_deu_mes | B40: Cuota Máximo por Endeudamiento Mensual | C40: =+C25*0.5-C28 -> 650000 | D40: Cálculo Motor | E40: Este cálculo implicitamente es mensual
A41: cuota_max_deu_frec | B41: Cuota Máximo por Endeudamiento Periódica | C41: =+C40/C34 -> 325000 | D41: Cálculo Motor
A42: cuota_max_cap_mes | B42: Cuota Máxima por Capacidad Mensual | C42: =IF((C37-C38-C39)<0,0,(C37-C38-C39)) -> 468368.6 | D42: Cálculo Motor | E42: Este cálculo implicitamente es mensual
A43: cuota_max_cap_frec | B43: Cuota Máxima por Capacidad Periódica | C43: =+C42/C34 -> 234184.3 | D43: Cálculo Motor
A44: cuota_max_fin | B44: Cuota Máxima por Capacidad | C44: =MIN(C43,C41) -> 234184.3 | D44: Cálculo Motor
...

Sheet Datos_Iniciales
B1: COOPVALILI
B2: MODELO ASIGNACION DE CREDITOS
B4: Crédito Afianzado | C4: 2
B6: Linea de Credito | C6: 19
B8: Tipo de Salario Asociado | C8: 1
B10: N° Cedula | C10: 1112878165 | Q10: 1 | R10: Semanal | S10: 52
B11: Salario | C11: =+INDEX(Base_Asociados!$B$6:$V$9877,MATCH(Datos_Iniciales!$C$10,Base_Asociados!$B$6:$B$9877,0),MATCH(Datos_Iniciales!$B11,Base_Asociados!$B$5:$V$5,0)) -> 1625000 | Q11: 2 | R11: Quincenal | S11: 24
B12: Otros Ingresos | Q12: 3 | R12: Mensual | S12: 12
B13: Egresos Volante de Pago | C13: 476010 | E13: 3
B14: Egresos Cuotas Sector | C14: 0
B15: Plazo en años | C15: 1
B16: Score Cifin | C16: =+VLOOKUP($C$10,Score_Cifin!$B$2:$C$1985,2,FALSE()) -> 657 | F16: 1
B17: Monto Solicitado | C17: 1400000 | E17: Cuota Cupo Tarjetas
B18: Cupos Tarjetas | C18: 4258000 | E18: =IF($F$16=1,-PMT(Parametros!$D$9,Parametros!D10,Datos_Iniciales!$C$18),0) -> 181631.4
B19: Aportes | C19: 1355255
B20: Deuda Coopvalili | C20: 2500671
B21: Deuda Sector | C21: 0
B22: Recoge Cuotas Coopvalili
B23: Recoge Cuotas Sector
B24: Cupo Rotativo Coopvalili
B25: Ahorros En El Fondo
B26: Usuario De Credito en Coopvalili | C26: 2592933
B27: Edad | C27: =+INDEX(Base_Asociados!$B$6:$V$9877,MATCH(Datos_Iniciales!$C$10,Base_Asociados!$B$6:$B$9877,0),MATCH(Datos_Iniciales!$B27,Base_Asociados!$B$5:$V$5,0)) -> 38
B28: Personas a Cargo | C28: =+INDEX(Base_Asociados!$B$6:$V$9877,MATCH(Datos_Iniciales!$C$10,Base_Asociados!$B$6:$B$9877,0),MATCH(Datos_Iniciales!$B28,Base_Asociados!$B$5:$V$5,0)) -> 0
B29: Tipo Vivienda | C29: =+INDEX(Base_Asociados!$B$6:$V$9877,MATCH(Datos_Iniciales!$C$10,Base_Asociados!$B$6:$B$9877,0),MATCH(Datos_Iniciales!$B29,Base_Asociados!$B$5:$V$5,0)) -> 4
B30: Antigüedad en la Cooperativa | C30: =+INDEX(Base_Asociados!$B$6:$V$9877,MATCH(Datos_Iniciales!$C$10,Base_Asociados!$B$6:$B$9877,0),MATCH(Datos_Iniciales!$B30,Base_Asociados!$B$5:$V$5,0)) -> 3.1583333
B31: Antigüedad Laboral | C31: =+INDEX(Base_Asociados!$B$6:$V$9877,MATCH(Datos_Iniciales!$C$10,Base_Asociados!$B$6:$B$9877,0),MATCH(Datos_Iniciales!$B31,Base_Asociados!$B$5:$V$5,0)) -> 3.4083333
B33: Pasivos | C33: =+C13+C14+E18 -> 657641.4
B34: Prenda
B35: Cesantias
C54: =+(Datos_Iniciales!$C$20+Datos_Iniciales!$C$21) -> 2500671

Sheet Hoja1
D2: Monto | E2: 98000000
D3: plazo | E3: 96
D4: tasa | E4: 0.0135
D5: cuota | E5: =+PMT(E4,E3,-E2) -> 1827365.1
D7: cuota real | E7: 1867588 | F7: =+E7-E5 -> 40222.887
D8: tasa real | E8: =RATE(E3,E7,-E2) -> 0.014076689
F9: =+F7*E3 -> 3861397.2

Sheet NIVEL ENERO
A1: 4661060 | B1: MINA ROBERTO CARLOS | C1: 0.39337458 | D1: 88218.54 | E1: Principal
A2: 5824652 | B2: CARVAJAL JIMENEZ CARLOS ANDRES | C2: 0.48223088 | D2: -222943 | E2: Principal
A3: 6537914 | B3: DELGADO ALVAREZ ALEXIS | C3: 0.1642021 | D3: 2109156 | E3: Principal
A4: 10280915 | B4: TRUJILLO ARANGO GERMAN HUMBERTO | C4: 0.47565441 | D4: -1187939.9 | E4: Principal
A5: 10285994 | B5: CORREA GARCIA ORLANDO | C5: 0.17595909 | D5: 1861721.8 | E5: Principal
A6: 11320970 | B6: HERNANDEZ CHAVEZ CARLOS HOLMES | C6: 0.42754621 | D6: -56033.88 | E6: Principal
A7: 14465776 | B7: CANAMEJOY GARCIA JUAN PABLO | C7: 0.46233948 | D7: -188224.8 | E7: Principal
A8: 14590768 | B8: LLOREDA MEJIA LUIS FRANCISCO | C8: 0.26518277 | D8: 1231980.9 | E8: Principal
A9: 14608714 | B9: DIAZ MENESES DAVID ORLANDO | C9: 0.18836387 | D9: 1768999.1 | E9: Principal
A10: 14621610 | B10: MUÑOZ VALERO ALVARO | C10: 0.22452655 | D10: 930825 | E10: Limonar
A11: 14837964 | B11: NIÑO MOTATO HUGO FERNANDO | C11: 0.36386528 | D11: 223252.68 | E11: Principal
A12: 14839579 | B12: TROCHEZ DELGADO JHON JAIRO | C12: 0.10864498 | D12: 1497029.2 | E12: Limonar
... A127: 34516193 | B127: GUAZA MEJIA ZULEIMA | C127: 0.46171638 | D127: -148886.6 | E127: Principal
A128: 34516353 | B128: OTALORA PALOMINO ILIEANA | C128: 0 | D128: 0 | E128: Principal
A129: 34558931 | B129: SANCHEZ HURTADO MARIA YANETH | C129: 0.31439015 | D129: 226464.3 | E129: Principal
A130: 34564166 | B130: ERIRA CEBALLOS EDIT MARGOT | C130: 0.47497047 | D130: -167545.94 | E130: Principal
A131: 34564544 | B131: MOSQUERA ARTEAGA NILSA YAZMIN | C131: 0.42709252 | D131: -34542 | E131: Principal
A132: 34615367 | B132: BOLAÑOS PAZ LEIDY JOHANNA | C132: 0.40885663 | D132: 101646.38 | E132: Principal
A133: 36175046 | B133: ALMARIO PERDOMO AMPARO | C133: 0.17543707 | D133: 1817304.1 | E133: Principal
A134: 38287868 | B134: TRIANA TRIVIÑO MARTHA ISABEL | C134: 0.14807781 | D134: 1120973.9 | E134: Principal
A135: 38462107 | B135: ORREGO FLOREZ MARLY SULEYDI | C135: 0.2973352 | D135: 872711 | E135: Principal
A136: 38556029 | B136: LOMBANA ESPINOSA CHARLENE ALEJANDRA | C136: 0.30426223 | D136: 950692.48 | E136: Principal
A137: 38557635 | B137: ANACONA HERNANDEZ YOLANDA LIRIA | C137: 0.53185456 | D137: -499894 | E137: Principal
A138: 38558372 | B138: OREJUELA GONZALEZ YOHANA | C138: 0.43525931 | D138: -59410.88 | E138: Principal
A139: 38559970 | B139: CORREA MUÑOZ LINDELIA | C139: 0.41803049 | D139: 6161.84 | E139: Principal
A140: 38560478 | B140: BONILLA VARGAS MARIA DEL PILAR | C140: 0.16654109 | D140: 2534437 | E140: Principal
... A166: 52026283 | B166: MURILLO ANZOLA ANGELA MARIA | C166: 0.27175196 | D166: 565041.62 | E166: Principal
A167: 52316905 | B167: GIL AMPUDIA CAROLINA | C167: 0 | D167: 0 | E167: Principal
A168: 55113244 | B168: DIAZ MONTEALEGRE SILVIA LORENA | C168: 0.12470916 | D168: 1911831 | E168: Principal
A169: 59666004 | B169: CASTILLO VALENTIERRA CARMEN MANUELA | C169: 0.16813129 | D169: 1226651 | E169: Principal
A170: 59801808 | B170: TREJO ROJAS DAYRA YAMILE | C170: 0.30446083 | D170: 391679.98 | E170: Limonar
A171: 59816941 | B171: VASQUEZ MUÑOZ DALY RIGUEY | C171: 0.20556673 | D171: 1161971 | E171: Principal
A172: 60328704 | B172: GOMEZ HERNANDEZ MARIA ELVIRA | C172: 0.40611388 | D172: 28792.24 | E172: Principal
A173: 60337190 | B173: PATIÑO BETANCOURT ANA JOSEFA | C173: 0.23162067 | D173: 1172699 | E173: Principal
A174: 60406095 | B174: PRATO HERNANDEZ ROSA MARGARITA | C174: 0.42961251 | D174: -56164 | E174: Limonar
A175: 66656138 | B175: MARTINEZ GUTIERREZ LUZBEIRA | C175: 0.50254482 | D175: -330105.48 | E175: Principal
A176: 66656378 | B176: CIFUENTES POSADA DORHIE ZULENY | C176: 0.26744638 | D176: 682292.08 | E176: Principal
A177: 66702591 | B177: LEON RIOS LILIANA | C177: 0.3193359 | D177: 453662.86 | E177: Principal
A178: 66718924 | B178: LOPEZ ARANA GISELA | C178: 0.42853835 | D178: -28986 | E178: Principal
A179: 66764802 | B179: ORTEGA ROJAS GLADYS | C179: 0.53298321 | D179: -352241.67 | E179: Principal
...
